Workbook

Sheet CA 1996
C2: CONTROL TRÁMITE DE CONCESIÓN DE AGUAS | BP2: Código | BQ2: RE-AA-20
BP3: Versión | BQ3: 8
BP4: Fecha | BQ4: 45617
A6: DATOS DE LA SOLICITUD | L6: REQUERIMIENTO | Q6: PAGO SERVICIOS DE EVALUACION | V6: AUTO | Y6: CONCEPTO TECNICO | AF6: REQUERIMIENTO | AK6: ACTO ADMINISTRATIVO | AR6: RECURSO DE REPOSICION | AT6: ACTO ADMINISTRATIVO RECURSO DE REPOSICION | AY6: MEMORIAS DE CALCULO | BH6: RECIBO A SATISFACCION DE OBRAS | BQ6: OBSERVACIONES
A7: No. Radicado | B7: Fecha Radicado | C7: No. Expediente | D7: Solicitante/Interesado | E7: Cédula de ciudadanía - NIT | F7: Municipio | G7: Vereda | H7: Tipo de Fuente | I7: Fuente | J7: Nombre de la Fuente | K7: Uso | L7: No. Oficio/ Auto de Requerimiento | M7: Fecha Oficio/ Auto de Requerimiento | N7: Nombre de quién proyectó | O7: Radicado Oficio de entrada | P7: Fecha oficio de entrada | Q7: No. de la Factura | R7: Valor tabla única (Factura) | S7: Valor Facturado | T7: Valor Cancelado | U7: Fecha del pago servicio de evaluación | V7: No. Auto admite y fija | W7: Fecha Auto admite y fija | X7: Nombre de quién proyectó | Y7: Fecha Visita técnica | Z7: Nombre del técnico | AA7: Fecha Concepto técnico | AB7: Caudal Fuente | AC7: Caudal Disponible | AD7: Caudal Otorgado | AE7: Número de Usuarios | AF7: No. Auto de Requerimiento | AG7: Fecha Auto de Requerimiento | AH7: Nombre de quién proyectó | AI7: Radicado Oficio de entrada | AJ7: Fecha oficio de entrada | AK7: No. Acto Administrativo | AL7: Fecha Acto Administrativo | AM7: Nombre de quién proyectó | AN7: Otorgada | AO7: Negada | AP7: Fecha Notificación | AQ7: Fecha ejecutoria | AR7: No. Radicado | AS7: Fecha Radicado | AT7: No. Acto Administrativo | AU7: Fecha Acto Administrativo | AV7: Nombre de quién proyectó | AW7: Modifica/ Aclara / Confirma/ Adiciona /Niega | AX7: Fecha Notificación | AY7: No. Radicado | AZ7: Fecha Radicado | BA7: Auto Requer. | BB7: Fecha Requer. | BC7: Nombre de quién proyecto | BD7: No. Acto Administrativo | BE7: Fecha Act Administrativo | BF7: Nombre de quien proyectó | BG7: Cumple o NO | BH7: No. Radicado del usuario | BI7: Fecha Radicado | BJ7: Fecha de visita técnica | BK7: Fecha Informe técnico | BL7: Nombre del técnico | BM7: No. Acto Administrativo | BN7: Fecha Acto Administrativo | BO7: Nombre de quién proyectó | BP7: Cumple o NO
A8: 2726 | B8: 32780 | C8: CA 160-96 | D8: ACUEDUCTO CHORRO BLANCO | E8: 4276408 | F8: TIBANA | G8: QUICHATOQUE | H8: SUPERFICIAL | I8: QUEBRADA | J8: CHORRO BLANCO | K8: DOMESTICO Y ABREVADERO | L8: N/A | M8: N/A | N8: N/A | O8: N/A | P8: N/A | Q8: N/A | R8: N/A | S8: N/A | T8: N/A | U8: N/A | V8: N/A | W8: N/A | X8: N/A | Y8: N/A | Z8: N/A | AA8: N/A | AB8: N/A | AC8: N/A | AD8: N/A | AE8: N/A | AF8: N/A | AG8: N/A | AH8: N/A | AI8: N/A | AJ8: N/A | AK8: RES 254 RES629 RES921 RES651 | AL8: 28/09/1990 02/09/1996 29/12/2000 23/08/2007 | AM8: N/A | AN8: X | AP8: 39349 | AQ8: 39356 | AR8: N/A | AS8: N/A | AT8: N/A | AU8: N/A | AV8: N/A | AW8: N/A | AX8: N/A | AY8: 2013ER5281 | AZ8: 41620 | BA8: N/A | BB8: N/A | BC8: N/A | BD8: 41739 | BE8: 41739 | BF8: HERCYV | BG8: SI | BH8: N/A | BI8: N/A | BJ8: N/A | BK8: N/A | BL8: N/A | BM8: 165 | BN8: 42822 | BO8: JULIAN SUAREZ | BP8: NO | BQ8: PARA PERDIDA DE FUERZA
A9: 1209 2007ER608 | B9: 15/11/1995 07/02/2007 | C9: CA 136-96 | D9: RODRIGO JOSE QUINTANA MUÑOZ Y OTROS | E9: 7167299 | F9: TURMEQUE | G9: ROSALES | H9: SUPERFICIAL | I9: NACIMIENTO | J9: EL MANANTIAL | K9: DOMESTICO PECUARIO AGRICOLA | V9: 3/06/1996 1443 | W9: 3/06/1996 02/11/2021 | X9: N/A | Y9: 35230 | AA9: 35115 | AB9: N/A | AC9: N/A | AD9: N/A | AE9: N/A | AF9: N/A | AG9: N/A | AH9: N/A | AI9: N/A | AJ9: N/A | AK9: RES 180 RES 238 RES 1195 | AL9: 27/02/1997 03/06/2011 08/11/2022 | AM9: NOHORA P PERILLA JEFER AVILA | AN9: X | AP9: 35508 | AQ9: 35521 | AR9: N/A | AS9: N/A | AT9: N/A | AU9: N/A | AV9: N/A | AW9: N/A | AX9: N/A | AY9: 808 2848 | AZ9: 24/02/2004 04/10/2023 | BA9: N/A | BB9: N/A | BC9: N/A | BD9: 461 750 162 | BE9: 10/06/2004 13/08/2025 23/02/2026 | BF9: YAMILE MILENA G | BG9: SI SI | BH9: 2004ER4579 | BI9: 38259 | BJ9: 38275 | BK9: 38309 | BL9: HENRY LESMES | BM9: 38315 | BN9: 38315 | BO9: YAMILE C | BP9: SI | BQ9: VIGENTE HASTA EL 2032
A10: 334 | B10: 35116 | C10: CA 267-96 | D10: ROBERTO RATIVA BERNAL | E10: 1008756 | F10: BOYACA | G10: VANEGAS | H10: SUPERFICIAL | I10: NACIMIENTO | J10: BUENOS AIRES | K10: DOMESTICO | L10: N/A | M10: N/A | N10: N/A | O10: N/A | P10: N/A | Q10: N/A | R10: N/A | S10: N/A | T10: N/A | U10: N/A | V10: N/A | W10: N/A | X10: N/A | Y10: N/A | Z10: N/A | AA10: N/A | AB10: N/A | AC10: N/A | AD10: N/A | AE10: N/A | AF10: N/A | AG10: N/A | AH10: N/A | AI10: N/A | AJ10: N/A | AK10: 1102 | AL10: 45650 | AM10: N/A | AO10: DESISTIDA | AP10: N/A | AQ10: N/A | AR10: N/A | AS10: N/A | AT10: N/A | AU10: N/A | AV10: N/A | AW10: N/A | AX10: N/A | AY10: N/A | AZ10: N/A | BA10: N/A | BB10: N/A | BC10: N/A | BD10: N/A | BE10: N/A | BF10: N/A | BG10: N/A | BH10: N/A | BI10: N/A | BJ10: N/A | BK10: N/A | BL10: N/A | BM10: N/A | BN10: N/A | BO10: N/A | BP10: N/A | BQ10: DESISTIDA PENDENTE NOTIFICACION Y ARCHIVO
A11: 2130 2018ER7751 | B11: 1/08/1996 23/10/2018 | C11: CA 356-96 | D11: MARTA PATRICIA PARRA | E11: 40015708 | F11: TIBANA | G11: PIEDRA DE CANDELA | H11: SUPERFICIAL | I11: NACIMIENTO | J11: TOPAGA Y PANTANOS | L11: N/A | M11: N/A | N11: N/A | O11: N/A | P11: N/A | Q11: N/A 623 | R11: N/A 146857 | S11: N/A 146857 | T11: N/A 3,000 146857 | U11: N/A 20/01/2007 23/10/2018 | V11: 29/08/1996 09/02/2007 318 | W11: 29/08/1996 09/02/2007 08/05/2019 | X11: NJR JEFER AVILA | Y11: 17/09/1996 27/02/2007 28/05/2019 20/02/2020 n/a | Z11: JOSE MIGUEL LARA JORGE MONROY JHHON RODRIGUEZ DIEGO MORENO | AA11: 17/09/1996 12/03/2007 30/05/2019 20/02/2020 01/11/2022 | AB11: 12LTS/SEG | AC11: N/A | AD11: N/A | AE11: N/A | AF11: N/A 6191 661 221 1718 0106 0483 | AG11: N/A 21/07/2005 09/09/2019 01/09/2022 12/03/2025 27/03/2026 | AH11: N/A NAYDA ROMERO y cuesta IVONE GUTIERREZ JUAN CRUZ LEO GOMEZ DANIEL RODRIGUEZ | AI11: N/A 2005ER5558 2019ER7559 3702 2022ER9868 | AJ11: N/A 21/09/2005 27/09/2019 19/06/2020 03/10/2022 | AK11: 1113 0467 MODIFICA 370 129 886 | AL11: 27/12/1996 11/07/1997 28/05/2007 04/02/2009 26/11/2019 | AM11: NOHORA MAURICIO ROJAS | AN11: X | AP11: 10/01/1996 08/10/1997 28/05/2007 24/03/2009 | AQ11: 35089 | AR11: N/A | AS11: N/A | AT11: N/A | AU11: N/A | AV11: N/A | AW11: N/A | AX11: N/A | AY11: 1766 5223 2020ER785 | AZ11: 22/04/2002 21/07/2009 07/02/2020 | BA11: N/A | BB11: N/A | BC11: N/A | BD11: 527 1418 | BE11: 2/08/2002 19/12/2022 | BF11: MERCEDES YEIMI GARCIA | BG11: SI | BH11: 6070 | BI11: 37483 | BJ11: 37601 | BK11: 37602 | BL11: heNRY LESMES | BQ11: EXPEDIENTE SE ENCUENTRA REQUERIDO DESDE EL 07/04/2026
A12: 3227 | B12: 35309 | C12: CA 115-96 | D12: ACUEDUCTO EL CEDRO | F12: NUEVO COLON | G12: CARBONERA SUR Y CENRO RURAL | H12: SUPERFICIAL | I12: NACIMIENTO | J12: EL CEDRO | K12: DOMESTICO Y ABREVADERO | L12: N/A | M12: N/A | N12: N/A | O12: N/A | P12: N/A | Q12: N/A | R12: N/A | S12: N/A | T12: 3000 | U12: N/A | V12: N/A 16/02/2006 281 | W12: N/A 16/02/2006 27/04/2017 | X12: N/A JAVIER FREDY PIÑEROS | Y12: N/A 06/02/2006 06/04/2016 11/08/2020 09/07/2021 | Z12: JOSE MIGUEL LARA ALFREDO RONALD RAMIREZ EDGAR MORENO angela RAMOS | AA12: 11/09/1995 29/03/2006 23/05/2016 28/08/2020 16/06/2021 | AB12: N/A 5,09 | AC12: N/A 0,83 | AD12: N/A 0,83 | AE12: 480 240 | AF12: 21/07/2005 28/09/2020 881 1841 | AG12: 21/07/2005 28/09/2020 21/12/2021 | AK12: 112 844 204 AMPLIA 329 ACUMULA Y PRORROGA 311 | AL12: 14/02/2026 01/08/2006 07/05/2015 30/06/2016 07/07/2017 | AM12: JAVIER C JULIAN S JEFER A MAIRA CARRILLO | AN12: X | AP12: 22/03/1996 29/08/2006 | AQ12: N/A | AR12: N/A | AS12: N/A | AT12: N/A | AU12: N/A | AV12: N/A | AW12: N/A | AX12: N/A | AY12: 2006ER5504 | AZ12: 39014 | BA12: 2009EE2553 | BB12: 2009EE2553 | BC12: DIANA JUANITA | BD12: 764 | BE12: 42725 | BF12: XIMENA B. | BG12: N/A | BH12: N/A | BI12: N/A | BJ12: N/A | BK12: N/A | BL12: N/A | BM12: N/A | BN12: N/A | BO12: N/A | BP12: N/A | BQ12: expediente fue requerido en 2021
A13: 3548 | B13: 35125 | C13: CA 292/96 | D13: RAFAEL MUÑOZ MORENO | E13: 1186479 | F13: VENTAQUEMADA | G13: CAPELLANIA | H13: SUPERFICIAL | I13: qUEBRADA | J13: RIO CACHUCHITA | K13: RIEGO | L13: N/A | M13: N/A | N13: N/A | O13: N/A | P13: N/A | Q13: N/A 0517 | R13: N/A | S13: N/A 6000 | T13: N/A 6000 | U13: N/A 08/08/1996 | V13: 3/06/1996 13/02/2006 | W13: 3/06/1996 13/02/2006 | X13: NJR JAVIER C | Y13: 19/06/1996 28/02/2006 | Z13: JOSE MIGUEL LARA alfredo | AA13: 19/06/2006 21/03/2006 | AB13: 513LTXS | AC13: 1,50LTS/S | AD13: 1,50LTS/S | AE13: 12 | AF13: N/A | AG13: N/A | AH13: N/A | AI13: N/A | AJ13: N/A | AK13: 570 01089 542 357 perdida fuerza ejec 1426 | AL13: 31/07/1996 29/11/2002 25/05/2006 19/05/2021 24/12/2024 | AM13: NOHORA MERCEDES javier c PAULA MORENO | AN13: X | AP13: 8/08/1996 12/06/2006 | AQ13: N/A | AR13: N/A | AS13: N/A | AT13: N/A | AU13: N/A | AV13: N/A | AW13: N/A | AX13: N/A | AY13: 4838 | AZ13: 37175 | BA13: 4821 | BB13: 37404 | BC13: ana elvia | BD13: 163 | BE13: 37708 | BF13: MERCEDES | BG13: SI | BH13: N/A | BI13: N/A | BJ13: N/A | BK13: N/A | BL13: N/A | BM13: 37886 | BN13: 37886 | BO13: MERCEDES | BP13: SI | BQ13: EXPEDIENTE SE ENCUENTRA REQUERIDO DESDE EL 24/12/2024 CON CITACION DE NOTIFICACION PERSONAL DE 27/12/2024
A14: 4014 | B14: 34436 | C14: CA4014/96 | D14: JOSE ARGEMIRO VELANDIA | E14: 19397583 | F14: NUEVO COLON | G14: FIOTA | H14: SUPERFICIAL | I14: NACIMIENTO | J14: LA RINCONADA | K14: DOMESTICO | L14: N/A | M14: N/A | N14: N/A | O14: N/A | P14: N/A | Q14: N/A 0388 | R14: N/A | S14: N/A 3000 | T14: N/A 3000 | U14: N/A 09/05/1996 | V14: N/A | W14: N/A 05/09/2016 | X14: N/A | Y14: 13/09/1995 27/11/2003 08/09/2004 06/04/2006 26/11/2011 10/12/2014 24/04/2018 28/07/2023 | Z14: RODRIGO CORREAL ALFREDO HENRY LESMES alexander CASTRO ANDRES CORTEZ JEISON SANCHEZ JAIDER ARIAS maria paula sanchez | AA14: 13/09/1995 22/01/2004 25/11/2004 01/11/2011 30/12/2014 10/07/2017 29/12/2023 | AB14: N/A | AC14: N/A | AD14: N/A | AE14: N/A | AF14: N/A 1057 4705 753 796 | AG14: N/A 02/02/2012 15/07/2016 24/08/2014 14/08/2024 | AH14: N/A JULIAN MORENO LORENA BARON leonardo gomez | AI14: N/A 2014ER4712 2016ER4699 | AJ14: N/A 08/10/2014 05/08/2014 | AK14: 108 619 300 235prorroga 713 corrige yerro | AL14: 13/02/1996 09/06/2006 26/03/2018 13/05/2019 01/10/2019 | AM14: JVED FRANCY MAURICIO ROJAS JAVIER ORTIZ | AN14: X | AP14: 35145 | AQ14: N/A | AR14: N/A | AS14: N/A | AT14: N/A | AU14: N/A | AV14: N/A | AW14: N/A | AX14: N/A | AY14: 4688 2019ER6305 | AZ14: 26/09/2000 12/08/2019 | BA14: N/A | BB14: N/A | BC14: N/A | BD14: N/A 0119 922 | BE14: N/A 28/03/2001 01/09/2022 | BF14: N/A juan ´pablo cruz | BG14: SI | BH14: 85 | BI14: 38043 | BJ14: 38078 | BK14: 38091 | BL14: HENRY LESMES | BM14: N/A | BN14: N/A | BO14: N/A | BP14: N/A | BQ14: Expediente se encuentra requerido de fecha 09/07/2026

Sheet CA 1997
C1: CONTROL TRAMITE DE CONCESION DE AGUAS 1997 | CF1: Código | CG1: RE-AA-20
CF2: Versión | CG2: 7
CF3: Fecha | CG3: 44411
A4: DATOS DE LA SOLICITUD | Q4: REQUERIMIENTO | X4: PAGO SERVICIOS DE EVALUACION | AC4: AUTO | AF4: CONTROL- DIAS TRANSCURRIDOS HASTA FECHA DE VISITA | AG4: CONCEPTO TECNICO | AT4: CONTROL- DIAS TRANSCURRIDOS DE LA RADICACION AL CONCEPTO CON Vo.Bo. | AV4: REQUERIMIENTO | BA4: ACTO ADMINISTRATIVO | BH4: RECURSO DE REPOSICION | BJ4: ACTO ADMINISTRATIVO RECURSO DE REPOSICION | BO4: MEMORIAS DE CALCULO | BX4: RECIBO A SATISFACCION DE OBRAS | CG4: OBSERVACIONES
A5: No. Radicado | B5: Fecha Radicado | C5: No. Expediente | D5: RADICADO EN VITAL | E5: Solicitante/Interesado | F5: Cédula de ciudadanía - NIT | G5: Dirección de correspondencia | H5: Municipio - CONCESION DE AGUAS | I5: Teléfono | J5: Correo Electrónico | K5: Lugar de la captación (Vereda) | L5: Tipo de Fuente | M5: Fuente | N5: Nombre de la Fuente | O5: Uso | P5: APERTURÓ | Q5: No. Oficio/ Auto de Requerimiento | R5: Fecha Oficio/ Auto de Requerimiento | S5: Nombre de quién proyectó | T5: DIAS DEL RADICADO AL REQUERIMIENTO | U5: Radicado Oficio de entrada | V5: Fecha oficio de entrada | W5: DESCRIPCION DEL REQUERIMIENTO | X5: No. de la Factura | Y5: Valor tabla única (Factura) | Z5: Valor Facturado | AA5: Valor Cancelado | AB5: Fecha del pago servicio de evaluación | AC5: No. Auto admite y fija | AD5: Fecha Auto admite y fija | AE5: Nombre de quién proyectó | AG5: Fecha Visita técnica | AH5: Nombre del técnico | AI5: FECHA LIMITE ENTREGA DE CONCEPTO | AJ5: DIAS CALENDARIO TRANSCURRIDOS SEGÚN FECHA LIMITE DE ENTRE DE CONCEPTO Y FECHA DE VISITA TECNICA | AK5: ALERTAS | AL5: Fecha entrega a Revisión Informe - Lider | AM5: Entrega de Informe al técnico para corrección | AN5: Entrega de concepto corregido | AO5: Fecha Concepto técnico | AP5: Caudal Fuente | AQ5: Caudal Disponible | AR5: Caudal Otorgado | AS5: Número de Usuarios | AU5: FECHA DE ASIGNACION CONCEPTO AL AREA JURIDICO | AV5: No. Auto de Requerimiento | AW5: Fecha Auto de Requerimiento | AX5: Nombre de quién proyectó | AY5: Radicado Oficio de entrada | AZ5: Fecha oficio de entrada | BA5: No. Acto Administrativo | BB5: Fecha Acto Administrativo | BC5: Nombre de quién proyectó | BD5: Otorgada | BE5: Negada | BF5: Fecha Notificación | BG5: Fecha ejecutoria | BH5: No. Radicado | BI5: Fecha Radicado | BJ5: No. Acto Administrativo | BK5: Fecha Acto Administrativo | BL5: Nombre de quién proyectó | BM5: Modifica/ Aclara / Confirma/ Adiciona /Niega | BN5: Fecha Notificación | BO5: No. Radicado | BP5: Fecha Radicado | BQ5: Auto Requer. | BR5: Fecha Requer. | BS5: Nombre de quién proyecto | BT5: No. Acto Administrativo | BU5: Fecha Act Administrativo | BV5: Nombre de quien proyectó | BW5: Cumple o NO | BX5: No. Radicado del usuario | BY5: Fecha Radicado | BZ5: Fecha de visita técnica | CA5: Fecha Informe técnico | CB5: Nombre del técnico | CC5: No. Acto Administrativo | CD5: Fecha Acto Administrativo | CE5: Nombre de quién proyectó | CF5: Cumple o NO | CH5: ULTIMA ACTULIZACION | CI5: FECHA ACTUALIZAICON
C6: CA 007-97 | Q6: 2025EE6209 | R6: 07/072025 | S6: KAREN BARRETO | U6: 2025ER6592 | V6: 45828 | CB6: NA | CC6: NA | CD6: NA | CE6: NA | CF6: NA | CG6: SE ACTUALIZO INFORMACION TOMO DOS | CH6: KAREN BARRETO | CI6: 45849
C7: C.A. 051/97 | E7: WILLIAM MANCIPE MANCIPE | F7: 3206495 | G7: Predio Buenos Aites Vereda San Josi Tibaná– Boyacá | H7: TIBANA | I7: 320 267 3336 - 311 462 1454 | J7: williammancipe79@gmail.com - hernanmanrtinez608@hotmail.com | K7: El Carmen San Jose | L7: SUPERFICIAL | M7: NACIMIENTO | N7: SAN PEDRO | O7: DOMESTICO AGRICOLA PECUARIO | P7: NA | Q7: NA | R7: NA | S7: NA | T7: NA | U7: NA | V7: NA | W7: NA | X7: NA | Y7: NA | Z7: NA | AA7: NA | AB7: NA | AC7: NA | AD7: NA | AE7: NA | AF7: NA | AG7: NA | AH7: NA | AI7: NA | AJ7: NA | AK7: NA | AL7: NA | AM7: NA | AN7: NA | AO7: NA | AP7: NA | AQ7: NA | AR7: NA | AS7: NA | AT7: NA | AU7: NA | AV7: NA | AW7: NA | AX7: NA | AY7: NA | AZ7: NA | BA7: NA | BB7: NA | BC7: NA | BD7: 549 537 344 | BE7: 29/08/2999 25/05/2006 30/06/2016 | BF7: 42578 | BG7: 42592 | BH7: NA | BI7: NA | BJ7: NA | BK7: NA | BL7: NA | BM7: NA | BN7: NA | BO7: NA | BP7: NA | BQ7: NA | BR7: NA | BS7: NA | BT7: NA | BU7: NA | BV7: NA | BW7: NA | BX7: NA | BY7: NA | BZ7: NA | CA7: NA | CB7: NA | CC7: NA | CD7: NA | CE7: NA | CF7: NA | CG7: Requerido mediante oficio No. 2026EE6396 -Prorroga y Modificación | CH7: MILENA GALINDO | CI7: 46183
C8: C.A 061-97 | E8: ACUEDUCTO URBANO DE TURMEQUE | F8: 820003743-2 | G8: carrera 1 con calle 1 | H8: TURMEQUE | I8: 3133415820 | J8: acueductoturmeque@hotmail.com | L8: SUPERFICIAL | M8: nacimiento | N8: El Gacal El Pedregral El Arrayan | O8: DOMESTICO | P8: NA | Q8: NA | R8: NA | S8: NA | T8: NA | U8: NA | V8: NA | W8: NA | X8: NA | Y8: NA | Z8: NA | AA8: NA | AB8: NA | AC8: NA | AD8: NA | AE8: NA | AF8: NA | AG8: NA | AH8: NA | AI8: NA | AJ8: NA | AK8: NA | AL8: NA | AM8: NA | AN8: NA | AO8: NA | AP8: NA | AQ8: NA | AR8: NA | AS8: NA | AT8: NA | AU8: NA | AV8: NA | AW8: NA | AX8: NA | AY8: NA | AZ8: NA | BA8: 51 930-Prorroga 360-Prorroga | BB8: 13/03/1998 27-10-08 19-06-2019 | BC8: Luis Alfondo Plinio Forero | BD8: x | BF8: 43675 | BG8: 43691 | BH8: NA | BI8: NA | BJ8: NA | BK8: NA | BL8: NA | BM8: NA | BN8: NA | BO8: 2021ER7374 | BP8: 40788 | BQ8: NA | BR8: NA | BS8: NA | BT8: RES1458 | BU8: 44483 | BV8: Jefer Avila | BW8: SI | BX8: 2022ER5691 | BY8: 44718 | BZ8: 44743 | CA8: 44750 | CB8: DIEGO MORENO | CC8: 778 | CD8: 44776 | CE8: JEVER AVILA | CF8: SI | CG8: Por medio del Auto No. 109 de fecha 30-02-2026 no se aprueba PUEAA y se realizo requerimiento con el fin de ajustar el PUEAA (30 dias) | CH8: karen Barreto | CI8: 46073
A9: 1997ER3787 | B9: 35695 | C9: CA 095-97 | E9: RIGOBERTO PULIDO MUÑOZ Y OTROS | F9: 4286627 | G9: Vereda Chirata | H9: Turmeque | I9: 3123815808 | J9: N/A | L9: SUPERFICIAL | M9: Nacimiento | N9: La Leontina | O9: Domestico Pecuario | P9: N/A | Q9: N/A | R9: N/A | S9: N/A | T9: N/A | U9: N/A | V9: N/A | W9: N/A | X9: N/A | Y9: N/A | Z9: N/A | AA9: N/A | AB9: N/A | AC9: N/A | AD9: N/A | AE9: N/A | AF9: N/A | AG9: N/A | AH9: N/A | AI9: N/A | AJ9: N/A | AK9: N/A | AL9: N/A | AM9: N/A | AN9: N/A | AO9: N/A | AP9: N/A | AQ9: N/A | AR9: N/A | AS9: N/A | AT9: N/A | AU9: N/A | AV9: N/A | AW9: N/A | AX9: N/A | AY9: N/A | AZ9: N/A | BA9: 723 450 596 | BB9: 30/12/1997 20/06/2007 30/09/2020 | BC9: ANA ELVIA ANA CELIA | BD9: X | BF9: 44109 | BG9: 44125 | BH9: N/A | BI9: N/A | BJ9: N/A | BK9: N/A | BL9: N/A | BM9: N/A | BN9: N/A | BO9: N/A | BP9: N/A | BQ9: N/A | BR9: N/A | BS9: N/A | BT9: N/A | BU9: 38714 | BV9: JUAN PABLO | BW9: SI | BX9: N/A | BY9: N/A | BZ9: N/A | CA9: N/A | CB9: N/A | CC9: N/A | CD9: N/A | CE9: N/A | CF9: N/A | CG9: Requerido mediante Auto No. 212 de 2025 | CH9: MILENA GALINDO | CI9: 45413
A10: 1997EE4749 | B10: 35754 | C10: CA 122-97 | E10: ASOCIACION DE SUSCRIPTORES DEL ACUEDUCTO JABONERA SUR DEL MUNICIPIO DE NUEVO COLON DEPARTAMENTO DE BOYACA | F10: 4182613 | G10: Jabonera Sur | H10: Nuevo Colon
C13: CONTROL TRÁMITE DE CONCESIÓN DE AGUAS | BP13: Código | BQ13: RE-AA-20
BP14: Versión | BQ14: 8
BP15: Fecha | BQ15: 45617
A17: DATOS DE LA SOLICITUD | L17: REQUERIMIENTO | Q17: PAGO SERVICIOS DE EVALUACION | V17: AUTO | Y17: CONCEPTO TECNICO | AF17: REQUERIMIENTO | AK17: ACTO ADMINISTRATIVO | AR17: RECURSO DE REPOSICION | AT17: ACTO ADMINISTRATIVO RECURSO DE REPOSICION | AY17: MEMORIAS DE CALCULO | BH17: RECIBO A SATISFACCION DE OBRAS | BQ17: OBSERVACIONES
A18: No. Radicado | B18: Fecha Radicado | C18: No. Expediente | D18: Solicitante/Interesado | E18: Cédula de ciudadanía - NIT | F18: Municipio | G18: Vereda | H18: Tipo de Fuente | I18: Fuente | J18: Nombre de la Fuente | K18: Uso | L18: No. Oficio/ Auto de Requerimiento | M18: Fecha Oficio/ Auto de Requerimiento | N18: Nombre de quién proyectó | O18: Radicado Oficio de entrada | P18: Fecha oficio de entrada | Q18: No. de la Factura | R18: Valor tabla única (Factura) | S18: Valor Facturado | T18: Valor Cancelado | U18: Fecha del pago servicio de evaluación | V18: No. Auto admite y fija | W18: Fecha Auto admite y fija | X18: Nombre de quién proyectó | Y18: Fecha Visita técnica | Z18: Nombre del técnico | AA18: Fecha Concepto técnico | AB18: Caudal Fuente | AC18: Caudal Disponible | AD18: Caudal Otorgado | AE18: Número de Usuarios | AF18: No. Auto de Requerimiento | AG18: Fecha Auto de Requerimiento | AH18: Nombre de quién proyectó | AI18: Radicado Oficio de entrada | AJ18: Fecha oficio de entrada | AK18: No. Acto Administrativo | AL18: Fecha Acto Administrativo | AM18: Nombre de quién proyectó | AN18: Otorgada | AO18: Negada | AP18: Fecha Notificación | AQ18: Fecha ejecutoria | AR18: No. Radicado | AS18: Fecha Radicado | AT18: No. Acto Administrativo | AU18: Fecha Acto Administrativo | AV18: Nombre de quién proyectó | AW18: Modifica/ Aclara / Confirma/ Adiciona /Niega | AX18: Fecha Notificación | AY18: No. Radicado | AZ18: Fecha Radicado | BA18: Auto Requer. | BB18: Fecha Requer. | BC18: Nombre de quién proyecto | BD18: No. Acto Administrativo | BE18: Fecha Act Administrativo | BF18: Nombre de quien proyectó | BG18: Cumple o NO | BH18: No. Radicado del usuario | BI18: Fecha Radicado | BJ18: Fecha de visita técnica | BK18: Fecha Informe técnico | BL18: Nombre del técnico | BM18: No. Acto Administrativo | BN18: Fecha Acto Administrativo | BO18: Nombre de quién proyectó | BP18: Cumple o NO
A19: 3879 | B19: 35407 | C19: CA 13/97 | D19: SANTIAGO ALFONSO VARGAS | E19: 4182699 | F19: NUEVO COLON | G19: JABONERA | H19: SUPERFICIAL | I19: NACIMIENTO | J19: EL PEDREGAL | K19: DOMESTICO | L19: N/A | M19: N/A | N19: N/A | O19: N/A | P19: N/A | Q19: N/A | R19: N/A | S19: N/A | T19: N/A | U19: N/A | V19: 13/01/1997 AUTO RENOV 05/02/2007 | W19: 13/01/1997 05/02/2007 | X19: NOHORA MERY | Y19: 28/02/1997 02/09/2004 19/02/2007 | Z19: JOSE MIGUEL LARA HENRY LESMES RAFAEL EDUARDO MORENO | AA19: 21/03/1997 02/09/2004 19/02/2007 | AB19: N/A 0,38 | AC19: N/A | AD19: 0,01 0,01 | AE19: 1 FAMILIA | AF19: N/A 1286 2352 | AG19: N/A 10/02/2005 21/03/2006 | AH19: N/A ALV | AI19: N/A 2006ER6762 | AJ19: N/A 27/12/2006 | AK19: 403 434 Prorroga 883 PERDIDA EJEC | AL19: 6/06/1997 15/06/2007 08/11/2024 | AM19: NOHORA riaño ALEJANDRA GUERRERO | AN19: X | AP19: 25/07/1997 21/11/2024 | AQ19: N/A | AR19: N/A | AS19: N/A | AT19: N/A | AU19: N/A | AV19: N/A | AW19: N/A | AX19: N/A | AY19: N/A | AZ19: N/A | BA19: N/A | BB19: N/A | BC19: N/A | BD19: N/A | BE19: N/A | BF19: N/A | BG19: N/A | BH19: N/A | BI19: N/A | BJ19: N/A | BK19: N/A | BL19: N/A | BM19: N/A | BN19: N/A | BO19: N/A | BP19: N/A | BQ19: Fecha actualizacion 23/09/2026 Yennyf ultima actuacion perdida de fuerza ejecutoria
A20: 3718 2018ER8654 | B20: 5/12/1996 27/11/2018 | C20: CA 04/97 | D20: LUIS ALFONSO ESPINOSA | E20: 4079569 | F20: CIENEGA | G20: TAPIAS | H20: SUPERFICIAL | I20: QUEBRADA TAPIAS | J20: POZO NEGRO | K20: RIEGO Y PECUARIA | L20: N/A | M20: N/A | N20: N/A | O20: N/A | P20: N/A | Q20: N/A 714 | R20: N/A 104756 | S20: N/A 104756 | T20: N/A 104756 | U20: N/A 08/02/2019 | V20: 13/01/1997 14/04/2008 RENOVA | W20: 13/01/1997 14/04/2008 | X20: NOHORA D SIERRA | Y20: 24/02/1997 22/06/2006 22/04/2008 04/11/2011 15/04/2019 17/06/2022 | Z20: JOSE MIGUEL LARA JUAN DAVID ASTRID CORTEZ LIZETH LOPEZ LINA SANTAMARIA | AA20: 3/04/1997 22/06/2006 13/05/2008 17/11/2012 23/04/2019 01/07/2022 | AB20: 1.33 | AC20: 1.33 | AD20: 1.61 | AE20: 3 FAMILIAS | AF20: N/A 1749 10554 5023 2019EE57 1603 2547 1993 | AG20: N/A 28/02/2006 27/11/2006 25/06/2007 03/01/2019 31/08/2022 09/11/2022 14/07/2023 | AH20: N/A FRANCY ALCIRA CRISTIAN MARTA SANCHEZ GERMAN RODRIGUEZ | AI20: N/A 2006ER1879 02871 2019ER1591 2022ER12379 | AJ20: N/A 17/04/2006 04/06/2007 06/03/2019 14/12/2022 | AK20: 398 778 179 ADM PRORRO 545 | AL20: 6/07/1997 08/09/2008 21/03/2019 12/08/2019 | AM20: NOHORA DSIERRA FREDY PIÑEROS JEFER AVILA | AN20: X | AP20: 2/02/1997 02/04/2019 | AQ20: N/A | AR20: N/A | AS20: N/A | AT20: N/A | AU20: N/A | AV20: N/A | AW20: N/A | AX20: N/A | AY20: 6613 | AZ20: 39792 | BA20: N/A | BB20: N/A | BC20: N/A | BD20: 39846 | BE20: 39847 | BF20: BFERERO | BG20: SI | BH20: N/A | BI20: N/A | BJ20: N/A | BK20: N/A | BL20: N/A | BM20: N/A | BN20: N/A | BO20: N/A | BP20: N/A | BQ20: Fecha actualizacion 23/09/2026 Yennyf ultima actuacion REQUERIDA
A21: 948 | B21: 35509 | C21: CA 37-97 | D21: JOSE LEVI SANCHEZ GONZALEZ | E21: 1159048 | F21: SOMONDOCO | G21: CUCUAVACA | I21: QUEBRADA LA HORCA | J21: SIN NOMBRE | K21: INDUSTRIAL | L21: N/A | M21: N/A | N21: N/A | O21: N/A | P21: N/A | Q21: N/A | R21: N/A | S21: N/A | T21: N/A | U21: N/A | V21: 17/04/1997 | W21: 35537 | X21: NOHORA | Y21: 3/06/1997 09/07/2006 18/01/2007 23/12/2010 25/04/2011 19/07/2011 16/10/2014 22/07/2015 | Z21: JOSE MIGUEL LARA JORGE MONROY WILSON LOZANO BLANCA CARO MARCO DURAN | AA21: 3/06/1997 29/06/2006 31/10/2006 07/01/2011 23/05/2011 19/08/2011 23/01/2012 04/12/2014 28/08/2015 | AB21: 4 | AC21: 4 | AD21: 3 | AE21: 1 FAMILIA | AF21: N/A 2942 5420 2006ee7005 5205 9529 2591 | AG21: N/A 05/04/2006 27/06/2006 30/08/2006 21/07/2009 20/10/2011 22/03/2012 | AH21: N/A FRANCY PRFD CAROLINA ROA | AI21: N/A 04317 2006ER2233 2006ER5258 2014ER3931 2015ER629 2015ER3317 | AJ21: N/A 20/10/1997 08/05/2006 10/10/2006 25/08/2014 12/02/2015 09/07/2015 | AK21: 507 701 APRUBAN PMA PARA INDUSTRIA 09/01/2007 admite renovac 272 PRORROGA 1105 | AL21: 12/08/1997 23/12/1997 07/05/2007 24/12/2024 | AM21: NOHORA PAULA MORENO | AN21: X | AP21: 20/08/1997 08/01/1998 | AQ21: N/A | AR21: N/A | AS21: N/A | AT21: N/A | AU21: N/A | AV21: N/A | AW21: N/A | AX21: N/A | AY21: N/A | AZ21: N/A | BA21: N/A | BB21: N/A | BC21: N/A | BD21: 39066 | BE21: 39066 | BF21: JAVIERC | BG21: SI | BH21: N/A | BI21: N/A | BJ21: N/A | BK21: N/A | BL21: N/A | BM21: 589 | BN21: 42286 | BO21: LORENA BARON | BP21: Cumple | BQ21: Fecha actualizacion 23/09/2026 Yennyf ultima actuacion perdida de fuerza ejecutoria EL SR FALLECIO
A22: 3565 | B22: 35681 | C22: 89/97 | D22: PARMENIO MENDOZA SUAREZ | E22: 133901 | F22: TIBANA | G22: JUANA RUIZ | J22: LAS CIRCAS | L22: N/A | M22: N/A | N22: N/A | O22: N/A | P22: N/A | Q22: N/A | R22: N/A | S22: N/A | T22: N/A | U22: N/A | V22: 35684 | W22: 35684 | X22: NOHORA | Y22: 28/11/1997 08/01/2003 17/06/2003 12/08/2003 18/05/2006 26/03/2008 21/10/2010 28/06/2011 14/12/2016 24/02/2017 | Z22: JOSE LARA HENRY LESMES ANDRES REYES ARMANDO MONROY WILSON LOZANO CARLOS ORTIZ DIEGO FARFAN LIZETH LOPEZ | AA22: 18/12/1997 26/01/2003 01/07/2003 12/08/2003 31/03/2008 011/2010 19/07/2011 27/12/2016 03/04/2017 | AB22: 0.43 | AC22: 0.43 | AD22: 0.06 | AE22: 35 FAMILIAS | AF22: N/A 2002 4958 2006EE6784 4011 369 7985 11850 AUTO REQUE 1029 3859 | AG22: N/A 12/05/2003 13/06/2006 10/05/2007 14/01/2011 24/08/2011 28/12/2011 30/10/2017 13/04/2023 | AH22: N/A JA MONROY SIERRA BRIYIT SACRISTAN LGRAMIREZ VANESA ROA KAREN BUITRAGO | AI22: N/A 01602 01777 4092 2007ER1564 2017ER3398 | AJ22: N/A 08/05/2003 21/05/2003 14/08/2006 21/03/2007 02/06/2017 | AK22: 83 auto 12/05/2003 AUTO 02/09/2003 AUTORENOVA 28/02/2008 783 915 273 NULIDAD 140 MODIFICA 1112 | AL22: 24/03/1998 28/02/2008 08/09/2008 27/10/2008 17/03/2009 05/04/2018 27/12/2024 | AM22: NOHORA SIERRA A MONSALVA JULIAN SUAREZ KAREN BARRETO | AN22: X | AP22: 29/04/1998 24/10/2008 19/06/2009 16/04/2018 | AQ22: N/A | AR22: N/A | AS22: N/A | AT22: N/A | AU22: N/A | AV22: N/A | AW22: N/A | AX22: N/A | AY22: N/A | AZ22: N/A | BA22: N/A | BB22: N/A | BC22: N/A | BD22: N/A | BE22: N/A | BF22: N/A | BG22: N/A | BH22: N/A | BI22: N/A | BJ22: N/A | BK22: N/A | BL22: N/A | BM22: N/A | BN22: N/A | BO22: N/A | BP22: N/A | BQ22: Fecha actualizacion 23/09/2026 Yennyf ultima actuacion perdida de fuerza ejecutoria NOTIFICACION POR CORREO

Sheet CA 1998
C1: CONTROL TRAMITE DE CONCESION DE AGUAS 1997 | CF1: Código | CG1: RE-AA-20
CF2: Versión | CG2: 7
CF3: Fecha | CG3: 44411
A4: DATOS DE LA SOLICITUD | Q4: REQUERIMIENTO | X4: PAGO SERVICIOS DE EVALUACION | AC4: AUTO | AF4: CONTROL- DIAS TRANSCURRIDOS HASTA FECHA DE VISITA | AG4: CONCEPTO TECNICO | AT4: CONTROL- DIAS TRANSCURRIDOS DE LA RADICACION AL CONCEPTO CON Vo.Bo. | AV4: REQUERIMIENTO | BA4: ACTO ADMINISTRATIVO | BH4: RECURSO DE REPOSICION | BJ4: ACTO ADMINISTRATIVO RECURSO DE REPOSICION | BO4: MEMORIAS DE CALCULO | BX4: RECIBO A SATISFACCION DE OBRAS | CG4: OBSERVACIONES
A5: No. Radicado | B5: Fecha Radicado | C5: No. Expediente | D5: RADICADO EN VITAL | E5: Solicitante/Interesado | F5: Cédula de ciudadanía - NIT | G5: Dirección de correspondencia | H5: Municipio - CONCESION DE AGUAS | I5: Teléfono | J5: Correo Electrónico | K5: Lugar de la captación (Vereda) | L5: Tipo de Fuente | M5: Fuente | N5: Nombre de la Fuente | O5: Uso | P5: APERTURÓ | Q5: No. Oficio/ Auto de Requerimiento | R5: Fecha Oficio/ Auto de Requerimiento | S5: Nombre de quién proyectó | T5: DIAS DEL RADICADO AL REQUERIMIENTO | U5: Radicado Oficio de entrada | V5: Fecha oficio de entrada | W5: DESCRIPCION DEL REQUERIMIENTO | X5: No. de la Factura | Y5: Valor tabla única (Factura) | Z5: Valor Facturado | AA5: Valor Cancelado | AB5: Fecha del pago servicio de evaluación | AC5: No. Auto admite y fija | AD5: Fecha Auto admite y fija | AE5: Nombre de quién proyectó | AG5: Fecha Visita técnica | AH5: Nombre del técnico | AI5: FECHA LIMITE ENTREGA DE CONCEPTO | AJ5: DIAS CALENDARIO TRANSCURRIDOS SEGÚN FECHA LIMITE DE ENTRE DE CONCEPTO Y FECHA DE VISITA TECNICA | AK5: ALERTAS | AL5: Fecha entrega a Revisión Informe - Lider | AM5: Entrega de Informe al técnico para corrección | AN5: Entrega de concepto corregido | AO5: Fecha Concepto técnico | AP5: Caudal Fuente | AQ5: Caudal Disponible | AR5: Caudal Otorgado | AS5: Número de Usuarios | AU5: FECHA DE ASIGNACION CONCEPTO AL AREA JURIDICO | AV5: No. Auto de Requerimiento | AW5: Fecha Auto de Requerimiento | AX5: Nombre de quién proyectó | AY5: Radicado Oficio de entrada | AZ5: Fecha oficio de entrada | BA5: No. Acto Administrativo | BB5: Fecha Acto Administrativo | BC5: Nombre de quién proyectó | BD5: Otorgada | BE5: Negada | BF5: Fecha Notificación | BG5: Fecha ejecutoria | BH5: No. Radicado | BI5: Fecha Radicado | BJ5: No. Acto Administrativo | BK5: Fecha Acto Administrativo | BL5: Nombre de quién proyectó | BM5: Modifica/ Aclara / Confirma/ Adiciona /Niega | BN5: Fecha Notificación | BO5: No. Radicado | BP5: Fecha Radicado | BQ5: Auto Requer. | BR5: Fecha Requer. | BS5: Nombre de quién proyecto | BT5: No. Acto Administrativo | BU5: Fecha Act Administrativo | BV5: Nombre de quien proyectó | BW5: Cumple o NO | BX5: No. Radicado del usuario | BY5: Fecha Radicado | BZ5: Fecha de visita técnica | CA5: Fecha Informe técnico | CB5: Nombre del técnico | CC5: No. Acto Administrativo | CD5: Fecha Acto Administrativo | CE5: Nombre de quién proyectó | CF5: Cumple o NO | CH5: ULTIMA ACTULIZACION | CI5: FECHA ACTUALIZAICON
C6: CA 039-98 | E6: ASOCIAICON DE SUSCRIPTORES ADUECUDTO EL TEJAR TEJAR ARRIBA TEJAR ABAJO Y CENTRO RURAL | F6: 900087289 | G6: NA | H6: NUEVO COLON | I6: 3123815808 | J6: acueductosncacutejar@gmail.com NCACUTEJAR@GMAIL.COM | K6: QUEBRADA EL ESPEJO | L6: Superficial | M6: Nacimiento | N6: QUEBRADA EL ESPEJO | O6: domestico | P6: N/A | Q6: 2025EE5138 2025EE10213 | R6: 10/06/2025 09/09/2025 | S6: KAREN BARRETO KAREN BARRETO | T6: N/A | U6: 2025ER5822 2025ER9561 | V6: 30/05/2025 25/08/2025 | W6: N/A | X6: N/A | Y6: N/A | Z6: N/A | AA6: N/A | AB6: N/A | AC6: N/A | AD6: N/A | AE6: N/A | AF6: N/A | AG6: N/A | AH6: N/A | AI6: N/A | AJ6: N/A | AK6: N/A | AL6: N/A | AM6: N/A | AN6: N/A | AO6: N/A | AP6: N/A | AQ6: N/A | AR6: N/A | AS6: N/A | AT6: N/A | AU6: N/A | AV6: N/A | AW6: N/A | AX6: N/A | AY6: N/A | AZ6: N/A | BA6: 484 | BB6: 36070 | BD6: X | BH6: N/A | BI6: N/A | BJ6: N/A | BK6: N/A | BL6: N/A | BM6: N/A | BN6: N/A | BO6: N/A | BP6: N/A | BQ6: N/A | BR6: N/A | BS6: N/A | BT6: N/A | BU6: 38714 | BV6: JUAN PABLO | BW6: SI | BX6: N/A | BY6: N/A | BZ6: N/A | CA6: N/A | CB6: N/A | CC6: N/A | CD6: N/A | CE6: N/A | CF6: N/A | CG6: DESISTIMIENTO TACITO 2025ER13626 DEL 18/12/20024 Y RADICADO 2025ER5822 DEL 30 DE MAYO | CH6: KAREN BARRETO | CI6: 45915
C9: CONTROL TRÁMITE DE CONCESIÓN DE AGUAS | BP9: Código | BQ9: RE-AA-20
BP10: Versión | BQ10: 8
BP11: Fecha | BQ11: 45617
A13: DATOS DE LA SOLICITUD | L13: REQUERIMIENTO | Q13: PAGO SERVICIOS DE EVALUACION | V13: AUTO | Y13: CONCEPTO TECNICO | AF13: REQUERIMIENTO | AK13: ACTO ADMINISTRATIVO | AR13: RECURSO DE REPOSICION | AT13: ACTO ADMINISTRATIVO RECURSO DE REPOSICION | AY13: MEMORIAS DE CALCULO | BH13: RECIBO A SATISFACCION DE OBRAS | BQ13: OBSERVACIONES
A14: No. Radicado | B14: Fecha Radicado | C14: No. Expediente | D14: Solicitante/Interesado | E14: Cédula de ciudadanía - NIT | F14: Municipio | G14: Vereda | H14: Tipo de Fuente | I14: Fuente | J14: Nombre de la Fuente | K14: Uso | L14: No. Oficio/ Auto de Requerimiento | M14: Fecha Oficio/ Auto de Requerimiento | N14: Nombre de quién proyectó | O14: Radicado Oficio de entrada | P14: Fecha oficio de entrada | Q14: No. de la Factura | R14: Valor tabla única (Factura) | S14: Valor Facturado | T14: Valor Cancelado | U14: Fecha del pago servicio de evaluación | V14: No. Auto admite y fija | W14: Fecha Auto admite y fija | X14: Nombre de quién proyectó | Y14: Fecha Visita técnica | Z14: Nombre del técnico | AA14: Fecha Concepto técnico | AB14: Caudal Fuente | AC14: Caudal Disponible | AD14: Caudal Otorgado | AE14: Número de Usuarios | AF14: No. Auto de Requerimiento | AG14: Fecha Auto de Requerimiento | AH14: Nombre de quién proyectó | AI14: Radicado Oficio de entrada | AJ14: Fecha oficio de entrada | AK14: No. Acto Administrativo | AL14: Fecha Acto Administrativo | AM14: Nombre de quién proyectó | AN14: Otorgada | AO14: Negada | AP14: Fecha Notificación | AQ14: Fecha ejecutoria | AR14: No. Radicado | AS14: Fecha Radicado | AT14: No. Acto Administrativo | AU14: Fecha Acto Administrativo | AV14: Nombre de quién proyectó | AW14: Modifica/ Aclara / Confirma/ Adiciona /Niega | AX14: Fecha Notificación | AY14: No. Radicado | AZ14: Fecha Radicado | BA14: Auto Requer. | BB14: Fecha Requer. | BC14: Nombre de quién proyecto | BD14: No. Acto Administrativo | BE14: Fecha Act Administrativo | BF14: Nombre de quien proyectó | BG14: Cumple o NO | BH14: No. Radicado del usuario | BI14: Fecha Radicado | BJ14: Fecha de visita técnica | BK14: Fecha Informe técnico | BL14: Nombre del técnico | BM14: No. Acto Administrativo | BN14: Fecha Acto Administrativo | BO14: Nombre de quién proyectó | BP14: Cumple o NO
A15: N/A 465 | B15: N/A 05/02/2004 | C15: CA 106/98 | D15: JOSE URIEL SANCHEZ TORRES | E15: N/A | F15: GARAGOA | G15: ACUEDUCTO INTERVEREDAL 1 | L15: 3159 05108 | M15: 4/07/2001 04/09/2001 | N15: NOHORA | O15: 3702 | P15: 37111 | Q15: N/A | R15: N/A | S15: N/A | T15: N/A | U15: N/A | V15: N/A | W15: N/A | X15: N/A | Y15: 37138 | Z15: HENRY LESMES | AA15: 37180 | AB15: N/A | AC15: N/A | AD15: N/A | AE15: N/A | AF15: N/A | AG15: N/A | AH15: N/A | AI15: N/A | AJ15: N/A | AK15: N/A | AL15: N/A | AM15: N/A | AN15: N/A | AO15: N/A | AP15: N/A | AQ15: N/A | AR15: N/A | AS15: N/A | AT15: N/A | AU15: N/A | AV15: N/A | AW15: N/A | AX15: N/A | AY15: N/A | AZ15: N/A | BA15: N/A | BB15: N/A | BC15: N/A | BD15: N/A | BE15: N/A | BF15: N/A | BG15: N/A | BH15: N/A | BI15: N/A | BJ15: N/A | BK15: N/A | BL15: N/A | BM15: N/A | BN15: N/A | BO15: N/A | BP15: N/A | BQ15: Fecha actualizacion 23/09/2026 Yennyf ultima actuacion memorando de fecha 23/02/2025

Sheet CA 1999
C1: CONTROL TRÁMITE DE CONCESIÓN DE AGUAS | BP1: Código | BQ1: RE-AA-20
BP2: Versión | BQ2: 8
BP3: Fecha | BQ3: 45617
A5: DATOS DE LA SOLICITUD | L5: REQUERIMIENTO | Q5: PAGO SERVICIOS DE EVALUACION | V5: AUTO | Y5: CONCEPTO TECNICO | AF5: REQUERIMIENTO | AK5: ACTO ADMINISTRATIVO | AR5: RECURSO DE REPOSICION | AT5: ACTO ADMINISTRATIVO RECURSO DE REPOSICION | AY5: MEMORIAS DE CALCULO | BH5: RECIBO A SATISFACCION DE OBRAS | BQ5: OBSERVACIONES
A6: No. Radicado | B6: Fecha Radicado | C6: No. Expediente | D6: Solicitante/Interesado | E6: Cédula de ciudadanía - NIT | F6: Municipio | G6: Vereda | H6: Tipo de Fuente | I6: Fuente | J6: Nombre de la Fuente | K6: Uso | L6: No. Oficio/ Auto de Requerimiento | M6: Fecha Oficio/ Auto de Requerimiento | N6: Nombre de quién proyectó | O6: Radicado Oficio de entrada | P6: Fecha oficio de entrada | Q6: No. de la Factura | R6: Valor tabla única (Factura) | S6: Valor Facturado | T6: Valor Cancelado | U6: Fecha del pago servicio de evaluación | V6: No. Auto admite y fija | W6: Fecha Auto admite y fija | X6: Nombre de quién proyectó | Y6: Fecha Visita técnica | Z6: Nombre del técnico | AA6: Fecha Concepto técnico | AB6: Caudal Fuente | AC6: Caudal Disponible | AD6: Caudal Otorgado | AE6: Número de Usuarios | AF6: No. Auto de Requerimiento | AG6: Fecha Auto de Requerimiento | AH6: Nombre de quién proyectó | AI6: Radicado Oficio de entrada | AJ6: Fecha oficio de entrada | AK6: No. Acto Administrativo | AL6: Fecha Acto Administrativo | AM6: Nombre de quién proyectó | AN6: Otorgada | AO6: Negada | AP6: Fecha Notificación | AQ6: Fecha ejecutoria | AR6: No. Radicado | AS6: Fecha Radicado | AT6: No. Acto Administrativo | AU6: Fecha Acto Administrativo | AV6: Nombre de quién proyectó | AW6: Modifica/ Aclara / Confirma/ Adiciona /Niega | AX6: Fecha Notificación | AY6: No. Radicado | AZ6: Fecha Radicado | BA6: Auto Requer. | BB6: Fecha Requer. | BC6: Nombre de quién proyecto | BD6: No. Acto Administrativo | BE6: Fecha Act Administrativo | BF6: Nombre de quien proyectó | BG6: Cumple o NO | BH6: No. Radicado del usuario | BI6: Fecha Radicado | BJ6: Fecha de visita técnica | BK6: Fecha Informe técnico | BL6: Nombre del técnico | BM6: No. Acto Administrativo | BN6: Fecha Acto Administrativo | BO6: Nombre de quién proyectó | BP6: Cumple o NO
A7: 6201 2015ER5742 | B7: 3/12/1999 26/11/2015 | C7: 067/99 | D7: DORA ELVIA JUNCO DE RODRIGUEZ | E7: 24160613 | F7: TIBANA | G7: APOSENTOS - IMBITA | H7: SUPERDIFICAL | I7: QUEBRADA | J7: QUEBRADA DE SORCA | K7: PECUARIO Y AGRICOLA | L7: N/A | M7: N/A | N7: N/A | O7: N/A | P7: N/A | Q7: N/A | R7: N/A | S7: N/A | T7: N/A | U7: N/A | V7: 9/12/1999 08/01/2010 29/12/2015 | W7: 9/12/1999 08/01/2010 29/12/2015 | X7: NOHORA DMANOSALVA JULIAN S | Y7: 10/04/2000 10/02/2010 30/09/2015 28/03/2016 01/11/2016 16/11/2022 | Z7: EDILBERTO MORENO REYES JORGE MONROY ANDREA OLIVEROS SERGIO DUEÑAS ELIANA CARDENAS JONATAN MUÑOZ | AA7: 10/04/2000 10/02/2010 10/11/2015 03/06/2016 01/11/2016 21/12/2022 | AB7: 8.12 | AC7: 8.12 | AD7: 2.25 | AE7: 10 | AF7: N/A 5269 264 0048 | AG7: N/A 21/07/2009 06/03/2023 15/01/2026 | AH7: N/A ARIOS GERMAN RODRIGUEZ ANGIE CRISTANCHO | AI7: N/A 2009ER6303 | AJ7: N/A 28/12/2009 | AK7: 16/08/1900 0164 PRORROGA 367 MODIFICA | AL7: 25/05/2000 17/02/2010 30/06/2016 | AM7: NOHORA PPERILLA LORENA BARON | AN7: X | AP7: 7/07/2000 18/03/2010 11/08/2016 | AQ7: N/A | AR7: N/A | AS7: N/A | AT7: N/A | AU7: N/A | AV7: N/A | AW7: N/A | AX7: N/A | AY7: N/A 2016ER6813 | AZ7: N/A 09/11/2016 | BA7: N/A | BB7: N/A | BC7: N/A | BD7: N/A 112 | BE7: N/A 03/05/2017 | BF7: N/A XIMENA BARRAGAN | BG7: N/A SI | BH7: N/A | BI7: N/A | BJ7: N/A | BK7: N/A | BL7: N/A | BM7: N/A | BN7: N/A | BO7: N/A | BP7: N/A | BQ7: Actualizada 23/09/2026 Yennyf Expediente se encuentra requerido desde el 15/01/2026
A8: 1531 2011ER460 | B8: 36271 | C8: CA 035/99 | D8: JOSE EUCARIO OSOARIO | E8: 79467076 | F8: TURMEQUE | G8: GUANZAQUE | H8: SUPERDIFICAL | J8: LA HONDURA | K8: ABREVADERO | L8: N/A | M8: N/A | N8: N/A | O8: N/A | P8: N/A | Q8: N/A | R8: N/A | S8: N/A | T8: N/A | U8: N/A | V8: 36278 | W8: 36278 | X8: NOHORA | Y8: 9/08/1999 21/10/2003 31/07/2008 15/02/2010 28/11/2018 | Z8: CARLOS SIERRA RAFAEL MORENO eliana cardenas | AA8: 9/08/1999 04/08/2008 28/04/2010 30/11/2018 | AB8: 1.25 | AC8: 1.25 | AD8: 0.07 | AE8: 19 FAMILIAS | AF8: N/A 5115 6541 2194 994 | AG8: N/A 24/10/2003 26/08/2006 06/04/2018 23/10/2020 | AH8: N/A YAMILE | AI8: N/A 2008ER5299 2009ER3092 | AJ8: N/A 08/10/2008 25/06/2009 | AK8: 378 AUTO ADM RENOVA 09/07/2009 025 PRORROGA | AL8: 8/09/1999 09/07/2009 07/02/2011 | AM8: NOHORA D MONSALVA P PERILLA | AN8: X | AP8: 22/09/1999 17/09/2012 | AQ8: N/A | AR8: N/A | AS8: N/A | AT8: N/A | AU8: N/A | AV8: N/A | AW8: N/A | AX8: N/A | AY8: N/A | AZ8: N/A | BA8: N/A | BB8: N/A | BC8: N/A | BD8: N/A | BE8: N/A | BF8: N/A | BG8: N/A | BH8: N/A | BI8: N/A | BJ8: N/A | BK8: N/A | BL8: N/A | BM8: N/A | BN8: N/A | BO8: N/A | BP8: N/A | BQ8: Actualizada 23/09/2026 Yennyf Expediente se encuentra para perdida de fuerza ejecutoria

Sheet CA 2000
A1: DATOS DE LA SOLICITUD | O1: APERTURÓ | P1: REQUERIMIENTO | W1: PAGO SERVICIOS DE EVALUACION | AB1: No. Oficio/ Auto de Requerimiento | AE1: CONTROL- DIAS TRANSCURRIDOS HASTA FECHA DE VISITA | AF1: CONCEPTO TECNICO | AV1: CONTROL- DIAS TRANSCURRIDOS DE LA RADICACION AL CONCEPTO CON Vo.Bo. | AW1: FECHA DE ASIGNACION CONCEPTO AL AREA JURIDICO | AX1: REQUERIMIENTO | BC1: ACTO ADMINISTRATIVO | BL1: RECURSO DE REPOSICION | BS1: MEMORIAS DE CALCULO | CB1: RECIBO A SATISFACCION DE OBRAS | CK1: ACTO ADMINISTRATIVO | EU1: SEGUIMIENTO | FD1: Observaciones de lo evidenciado en la visita técnica | FE1: Ultima Actualización
A2: No. Radicado | B2: Fecha Radicado | C2: No. Expediente | D2: RADICADO EN VITAL | E2: Solicitante/Interesado | F2: Cédula de ciudadanía - NIT | G2: Dirección de correspondencia | H2: Telefono | I2: Correo Electrónico | J2: Municipio permiso | K2: Lugar de la captación (Vereda) | L2: Tipo de Fuente | M2: Fuente | N2: Nombre de la Fuente | P2: No. Oficio/ Auto de Requerimiento | Q2: Fecha Oficio/ Auto de Requerimiento | R2: Nombre de quién proyectó | S2: Dias del radicado al requerimiento | T2: Descripcion del requerimiento | U2: Radicado Oficio de entrada | V2: Fecha oficio de entrada | W2: No. de la Factura | X2: Valor tabla única (Factura) | Y2: Valor Facturado | Z2: Valor Cancelado | AA2: Fecha del pago servicio de evaluación | AB2: No. Oficio/ Auto de Requerimiento | AC2: Fecha Oficio/ Auto de Requerimiento | AD2: Nombre de quién proyectó | AF2: Fecha Visita técnica | AG2: Nombre del técnico | AH2: FECHA LIMITE ENTREGA DE CONCEPTO | AI2: DIAS CALENDARIO TRANSCURRIDOS SEGÚN FECHA LIMITE DE ENTRE DE CONCEPTO Y FECHA DE VISITA TECNICA | AJ2: ALERTAS | AK2: Fecha entrega a Revisión Informe - Lider | AL2: Entrega de Informe al técnico para corrección | AM2: Entrega de concepto corregido | AN2: Fecha Concepto técnico | AO2: Predio a beneficiar | AP2: Georreferenciación del punto de captación | AQ2: Vereda de la localización del punto de captación | AR2: Usos | AS2: Caudal Otordo, dicriminado por cada uso | AT2: Total del caudal otorgado | AU2: Número de Suscriptores | AX2: No. Auto de Requerimiento | AY2: Fecha Auto de Requerimiento | AZ2: Nombre de quién proyectó | BA2: Radicado Oficio de entrada | BB2: Fecha oficio de entrada | BC2: No. Acto Administrativo | BD2: Fecha Acto Administrativo | BE2: Nombre de quién proyectó | BF2: Otorgada | BG2: Negada | BH2: Desistida | BI2: Fecha Notificación | BJ2: Fecha ejecutoria | BK2: Fecha de vencimiento | BL2: No. Radicado | BM2: Fecha Radicado | BN2: No. Acto Administrativo | BO2: Fecha Acto Administrativo | BP2: Nombre de quién proyectó | BQ2: Modifica/ Aclara / Confirma/ Adiciona /Niega | BR2: Fecha Notificación | BS2: No. Radicado | BT2: Fecha Radicado | BU2: Auto Requer. | BV2: Fecha Requer. | BW2: Nombre de quién proyecto | BX2: No. Acto Administrativo | BY2: Fecha Act Administrativo | BZ2: Nombre de quien proyectó | CA2: Cumple o NO | CB2: No. Radicado del usuario | CC2: Fecha Radicado | CD2: Fecha de visita técnica | CE2: Fecha Informe técnico | CF2: Nombre del técnico | CG2: No. Acto Administrativo | CH2: Fecha Acto Administrativo | CI2: Nombre de quién proyectó | CJ2: Cumple o NO | CK2: No. Radicado | CL2: Fecha Radicado | CM2: Fecha de visita técnica | CN2: Fecha Informe técnico | CO2: Nombre del técnico | CP2: No. Acto Administrativo | CQ2: Fecha de notificación | CR2: Fecha de ejecutoria | CS2: Observación | CT2: No. Radicado | CU2: Fecha Radicado | CV2: Fecha de visita técnica | CW2: Fecha Informe técnico | CX2: Nombre del técnico | CY2: No. Acto Administrativo | CZ2: Fecha de notificación | DA2: Fecha de ejecutoria | DB2: Observación | DC2: No. Radicado | DD2: Fecha Radicado | DE2: Fecha de visita técnica | DF2: Fecha Informe técnico | DG2: Nombre del técnico | DH2: No. Acto Administrativo | DI2: Fecha de notificación | DJ2: Fecha de ejecutoria | DK2: Observación | DL2: No. Radicado | DM2: Fecha Radicado | DN2: Fecha de visita técnica | DO2: Fecha Informe técnico | DP2: Nombre del técnico | DQ2: No. Acto Administrativo | DR2: Fecha de notificación | DS2: Fecha de ejecutoria | DT2: Observación | DU2: No. Radicado | DV2: Fecha Radicado | DW2: Fecha de visita técnica | DX2: Fecha Informe técnico | DY2: Nombre del técnico | DZ2: No. Acto Administrativo | EA2: Fecha de notificación | EB2: Fecha de ejecutoria | EC2: Observación | ED2: No. Radicado | EE2: Fecha Radicado | EF2: Fecha de visita técnica | EG2: Fecha Informe técnico | EH2: Nombre del técnico | EI2: No. Acto Administrativo | EJ2: Fecha de notificación | EK2: Fecha de ejecutoria | EL2: Observación | EM2: Fecha Radicado | EN2: Fecha de visita técnica | EO2: Fecha Informe técnico | EP2: Nombre del técnico | EQ2: RECLAMACION TUA | ER2: Fecha de notificación | ES2: Fecha de ejecutoria | ET2: Observación | EU2: Fecha ultimo seguimiento | EV2: Fecha de concepto | EW2: Cadual Aforado (Captado o vertido) | EX2: Volumen metros cubicos aprovechado ( AF) aprovechamiento forestal | EY2: Entrega informes Anuales (L.A) Solo aplica para licencias ambientales | FB2: Acto administrativo
AV3: Solicitamos se agregue la formula | CP3: Modificacion | CY3: Traspaso | DH3: Prorroga | DQ3: Cancelación | DZ3: Perdida de fuerza ejecutoria | EI3: Suspensión | EY3: Llantas Usadas | EZ3: ICA | FA3: Autoliquidación de la vigencia | FB3: N° | FC3: Fecha
EY5: SI /NO
A6: 2025ER13098 | B6: 45960 | E6: Acuducto caldera-ASUPAL | F6: 901406724-6 | G6: vereda caldera abajo | H6: 3167529752 | I6: marthacpineda@hotmail.com | J6: Garagoa | K6: Caldera arriba, caldera abajo quigua abajo, y las escuelas de las veredas caldera arriba y abajo | N6: chorro caldera | P6: 2025EE13610 | Q6: 45975 | R6: Karen Barreto | BC6: 370 332 119 | BD6: 11/07/2000 09-07-2013 08-03-2024 | BF6: otorgo prorroga prorroga | BL6: NA | BM6: NA | BN6: NA | BO6: NA | BP6: NA | BQ6: NA | BR6: NA | BS6: 2024ER4994 | BT6: 45806 | BX6: Res 567 | BY6: 45503 | BZ6: Milena Galindo | CA6: si | CB6: 2024ER9659 | CC6: 45558 | CD6: 45612 | CE6: 45645 | CF6: Andres T | CG6: Res 1139 | CH6: 45653 | CI6: Karen Barreto | CJ6: si | CK6: NA | CL6: NA | CM6: NA | CN6: NA | CO6: NA | CP6: NA | CQ6: NA | CR6: NA | CS6: NA | CT6: NA | CU6: NA | CV6: AN | CW6: NA | CX6: NA | CY6: NA | CZ6: NA | DA6: NA | DB6: NA | DC6: NA | DD6: NA | DE6: NA | DF6: NA | DG6: NA | DH6: NA | DI6: NA | DJ6: NA | DK6: NA | DL6: NA | DM6: NA | DN6: NA | DO6: NA | DP6: NA | DQ6: NA | DR6: NA | DS6: NA | DT6: NA | EU6: NA | EV6: NA | EW6: NA | EX6: NA | EY6: NA | EZ6: NA | FA6: NA | FB6: NA | FC6: NA | FD6: en tramite de actualizacion de representante legal 2025EE13610 | FE6: 45994 | FF6: KAREN BARRETO
C7: CA 069-00 | E7: ASOCIACION DE SUSCRIPTORES DE LA VEREDA DE CHAGUATA BOYACA ASAC SANTA ROSA | F7: 900432356 | G7: vereda chaguatoque | H7: 310 334 1156 | I7: carleon07@gmail.com | J7: tenza | P7: 2024EE8425 2025EE828 2025EE1427 2025EE3252 2025EE3253 | Q7: 3/09/2024 21/02/2025 14/03/2025 05/05/2025 05/05/2025 | R7: KAREN BARRETO ANGIE ALVAREZ KAREN BARRETO KAREN BARRETO KAREN BARRETO | U7: 2024ER8082 2025ER873 2025ER963 2025ER2690 | V7: 22/08/2024 04/02/2025 06/02/2025 25/03/2025 | W7: EV -23 | X7: 156585 | Y7: 156585 | Z7: 156585 | AA7: 45741 | AB7: 239 | AC7: 45779 | AD7: KAREN BARRETO | BC7: 285 418 | BD7: 29/06/201 07/07/2014 | BF7: OTORGO PRORROGA | BG7: NA | BH7: NA | DE7: 45797 | DF7: 45854 | DG7: adrian | DH7: requerido Auto No. 1285 | DI7: 45882 | FD7: requerido para allegar autorizacion sanitaria favorable | FE7: 45912 | FF7: MILENA GALINDO
A8: 200ER6107 | B8: 36887 | C8: CA 103-00 | D8: PENDIENTE | E8: JOSE RAMON SUAREZ SANTUARIO | F8: 1181410 | G8: VEREDA ROSALES | H8: 3108854907 | I8: NA | J8: TURMEQUE | K8: NA | L8: NA | M8: NA | N8: NA | O8: NA | P8: NA | Q8: NA | R8: NA | S8: NA | T8: NA | U8: NA | V8: NA | W8: NA | X8: NA | Y8: NA | Z8: NA | AA8: NA | AB8: NA | AC8: NA | AD8: NA | AE8: NA | AF8: NA | AG8: NA | AH8: NA | AI8: NA | AJ8: NA | AK8: NA | AL8: NA | AM8: NA | AN8: NA | AO8: NA | AP8: NA | AQ8: NA | AR8: NA | AS8: NA | AT8: NA | AU8: NA | AV8: NA | AW8: NA | AX8: NA | AY8: NA | AZ8: NA | BA8: NA | BB8: NA | BC8: NA | BD8: NA | BE8: NA | BF8: NA | BG8: NA | BH8: NA | BI8: NA | BJ8: NA | BK8: NA | BL8: NA | BM8: NA | BN8: NA | BO8: NA | BP8: NA | BQ8: NA | BR8: NA | BS8: NA | BT8: NA | BU8: NA | BV8: NA | BW8: NA | BX8: NA | BY8: NA | BZ8: NA | CA8: NA | CB8: NA | CC8: NA | CD8: NA | CE8: NA | CF8: NA | CG8: NA | CH8: NA | CI8: NA | CJ8: NA | CK8: NA | CL8: NA | CM8: NA | CN8: NA | CO8: NA | CP8: NA | CQ8: NA | CR8: NA | CS8: NA | CT8: NA | CU8: NA | CV8: NA | CW8: NA | CX8: NA | CY8: NA | CZ8: NA | DA8: NA | DB8: NA | DC8: NA | DD8: NA | DE8: NA | DF8: NA | DG8: NA | DH8: NA | DI8: NA | DJ8: NA | DK8: NA | DL8: NA | DM8: NA | DN8: NA | DO8: NA | DP8: NA | DQ8: NA | DR8: NA | DS8: NA | DT8: NA | DU8: NA | DV8: NA | DW8: NA | DX8: NA | DY8: NA | DZ8: NA | EA8: NA | EB8: NA | EC8: NA | ED8: NA | EE8: NA | EF8: NA | EG8: NA | EH8: NA | EI8: NA | EJ8: NA | EK8: NA | EL8: NA | EM8: NA | EN8: NA | EO8: NA | EP8: NA | EQ8: NA | ER8: NA | ES8: NA | ET8: NA | EU8: NA | EV8: NA | EW8: NA | EX8: NA | EY8: NA | EZ8: NA | FA8: NA | FB8: NA | FC8: NA | FD8: MEDIANTE RESOLUCION 778 DEL 20/08/2025 SE ARCHIVA EL EXPEDIENTE Actuacion notificada por aviso el día 16-12-2025 | FE8: 46013 | FF8: KAREN BARRETO

Sheet CA 2001
C1: CONTROL TRAMITE DE CONCESION DE AGUAS 2001 | CF1: Código | CG1: RE-AA-20
CF2: Versión | CG2: 7
CF3: Fecha | CG3: 44411
A4: DATOS DE LA SOLICITUD | Q4: REQUERIMIENTO | X4: PAGO SERVICIOS DE EVALUACION | AC4: AUTO | AF4: CONTROL- DIAS TRANSCURRIDOS HASTA FECHA DE VISITA | AG4: CONCEPTO TECNICO | AT4: CONTROL- DIAS TRANSCURRIDOS DE LA RADICACION AL CONCEPTO CON Vo.Bo. | AV4: REQUERIMIENTO | BA4: ACTO ADMINISTRATIVO | BH4: RECURSO DE REPOSICION | BJ4: ACTO ADMINISTRATIVO RECURSO DE REPOSICION | BO4: MEMORIAS DE CALCULO | BX4: RECIBO A SATISFACCION DE OBRAS | CG4: OBSERVACIONES
A5: No. Radicado | B5: Fecha Radicado | C5: No. Expediente | D5: RADICADO EN VITAL | E5: Solicitante/Interesado | F5: Cédula de ciudadanía - NIT | G5: Dirección de correspondencia | H5: Municipio - CONCESION DE AGUAS | I5: Teléfono | J5: Correo Electrónico | K5: Lugar de la captación (Vereda) | L5: Tipo de Fuente | M5: Fuente | N5: Nombre de la Fuente | O5: Uso | P5: APERTURÓ | Q5: No. Oficio/ Auto de Requerimiento | R5: Fecha Oficio/ Auto de Requerimiento | S5: Nombre de quién proyectó | T5: DIAS DEL RADICADO AL REQUERIMIENTO | U5: Radicado Oficio de entrada | V5: Fecha oficio de entrada | W5: DESCRIPCION DEL REQUERIMIENTO | X5: No. de la Factura | Y5: Valor tabla única (Factura) | Z5: Valor Facturado | AA5: Valor Cancelado | AB5: Fecha del pago servicio de evaluación | AC5: No. Auto admite y fija | AD5: Fecha Auto admite y fija | AE5: Nombre de quién proyectó | AG5: Fecha Visita técnica | AH5: Nombre del técnico | AI5: FECHA LIMITE ENTREGA DE CONCEPTO | AJ5: DIAS CALENDARIO TRANSCURRIDOS SEGÚN FECHA LIMITE DE ENTRE DE CONCEPTO Y FECHA DE VISITA TECNICA | AK5: ALERTAS | AL5: Fecha entrega a Revisión Informe - Lider | AM5: Entrega de Informe al técnico para corrección | AN5: Entrega de concepto corregido | AO5: Fecha Concepto técnico | AP5: Caudal Fuente | AQ5: Caudal Disponible | AR5: Caudal Otorgado | AS5: Número de Usuarios | AU5: FECHA DE ASIGNACION CONCEPTO AL AREA JURIDICO | AV5: No. Auto de Requerimiento | AW5: Fecha Auto de Requerimiento | AX5: Nombre de quién proyectó | AY5: Radicado Oficio de entrada | AZ5: Fecha oficio de entrada | BA5: No. Acto Administrativo | BB5: Fecha Acto Administrativo | BC5: Nombre de quién proyectó | BD5: Otorgada | BE5: Negada | BF5: Fecha Notificación | BG5: Fecha ejecutoria | BH5: No. Radicado | BI5: Fecha Radicado | BJ5: No. Acto Administrativo | BK5: Fecha Acto Administrativo | BL5: Nombre de quién proyectó | BM5: Modifica/ Aclara / Confirma/ Adiciona /Niega | BN5: Fecha Notificación | BO5: No. Radicado | BP5: Fecha Radicado | BQ5: Auto Requer. | BR5: Fecha Requer. | BS5: Nombre de quién proyecto | BT5: No. Acto Administrativo | BU5: Fecha Act Administrativo | BV5: Nombre de quien proyectó | BW5: Cumple o NO | BX5: No. Radicado del usuario | BY5: Fecha Radicado | BZ5: Fecha de visita técnica | CA5: Fecha Informe técnico | CB5: Nombre del técnico | CC5: No. Acto Administrativo | CD5: Fecha Acto Administrativo | CE5: Nombre de quién proyectó | CF5: Cumple o NO | CH5: ULTIMA ACTULIZACION | CI5: FECHA ACTUALIZAICON
A6: 2001EE5425 | B6: 37211 | C6: CA 055-01 | E6: LUIS ALFREDO GAMBA JUNCO | F6: 1098568 | G6: Calle 3 No. 4-23 | H6: Nuevo Colon | I6: 3105578793 | J6: frutasyverduraselcarpo@gmail.com | K6: Centro Rural | L6: Superficial | M6: Quebrada | N6: Grande | O6: Agricola | P6: N/A | Q6: N/A | R6: N/A | S6: N/A | T6: N/A | U6: N/A | V6: N/A | W6: N/A | X6: N/A | Y6: N/A | Z6: N/A | AA6: N/A | AB6: N/A | AC6: N/A | AD6: N/A | AE6: N/A | AF6: N/A | AG6: N/A | AH6: N/A | AI6: N/A | AJ6: N/A | AK6: N/A | AL6: N/A | AM6: N/A | AN6: N/A | AO6: N/A | AP6: N/A | AQ6: N/A | AR6: N/A | AS6: N/A | AT6: N/A | AU6: N/A | AV6: N/A | AW6: N/A | AX6: N/A | AY6: N/A | AZ6: N/A | BA6: 260 476 | BB6: 16/05/2002 23-09-2013 | BC6: ANA ELVIA ANA CELIA | BD6: X | BF6: 29/05/2002 15-10-2013 | BG6: 41576 | BH6: N/A | BI6: N/A | BJ6: N/A | BK6: N/A | BL6: N/A | BM6: N/A | BN6: N/A | BO6: N/A | BP6: N/A | BQ6: N/A | BR6: N/A | BS6: N/A | BT6: N/A | BU6: 38714 | BV6: JUAN PABLO | BW6: SI | BX6: N/A | BY6: N/A | BZ6: N/A | CA6: N/A | CB6: N/A | CC6: 1343 | CD6: 39081 | CE6: PLINIO RONALDO | CF6: SI | CG6: SE DESISTIO SOLICITUD DE PRORROGA ENVIAR A PERDIDA | CH6: MILENA GALINDO | CI6: 45413

Sheet CA 2002
C1: CONTROL TRAMITE DE CONCESION DE AGUAS 2002 | CF1: Código | CG1: RE-AA-20
CF2: Versión | CG2: 7
CF3: Fecha | CG3: 44411
A4: DATOS DE LA SOLICITUD | Q4: REQUERIMIENTO | X4: PAGO SERVICIOS DE EVALUACION | AC4: AUTO | AF4: CONTROL- DIAS TRANSCURRIDOS HASTA FECHA DE VISITA | AG4: CONCEPTO TECNICO | AT4: CONTROL- DIAS TRANSCURRIDOS DE LA RADICACION AL CONCEPTO CON Vo.Bo. | AV4: REQUERIMIENTO | BA4: ACTO ADMINISTRATIVO | BH4: RECURSO DE REPOSICION | BJ4: ACTO ADMINISTRATIVO RECURSO DE REPOSICION | BO4: MEMORIAS DE CALCULO | BX4: RECIBO A SATISFACCION DE OBRAS | CG4: OBSERVACIONES
A5: No. Radicado | B5: Fecha Radicado | C5: No. Expediente | D5: RADICADO EN VITAL | E5: Solicitante/Interesado | F5: Cédula de ciudadanía - NIT | G5: Dirección de correspondencia | H5: Municipio - CONCESION DE AGUAS | I5: Teléfono | J5: Correo Electrónico | K5: Lugar de la captación (Vereda) | L5: Tipo de Fuente | M5: Fuente | N5: Nombre de la Fuente | O5: Uso | P5: APERTURÓ | Q5: No. Oficio/ Auto de Requerimiento | R5: Fecha Oficio/ Auto de Requerimiento | S5: Nombre de quién proyectó | T5: DIAS DEL RADICADO AL REQUERIMIENTO | U5: Radicado Oficio de entrada | V5: Fecha oficio de entrada | W5: DESCRIPCION DEL REQUERIMIENTO | X5: No. de la Factura | Y5: Valor tabla única (Factura) | Z5: Valor Facturado | AA5: Valor Cancelado | AB5: Fecha del pago servicio de evaluación | AC5: No. Auto admite y fija | AD5: Fecha Auto admite y fija | AE5: Nombre de quién proyectó | AG5: Fecha Visita técnica | AH5: Nombre del técnico | AI5: FECHA LIMITE ENTREGA DE CONCEPTO | AJ5: DIAS CALENDARIO TRANSCURRIDOS SEGÚN FECHA LIMITE DE ENTRE DE CONCEPTO Y FECHA DE VISITA TECNICA | AK5: ALERTAS | AL5: Fecha entrega a Revisión Informe - Lider | AM5: Entrega de Informe al técnico para corrección | AN5: Entrega de concepto corregido | AO5: Fecha Concepto técnico | AP5: Caudal Fuente | AQ5: Caudal Disponible | AR5: Caudal Otorgado | AS5: Número de Usuarios | AU5: FECHA DE ASIGNACION CONCEPTO AL AREA JURIDICO | AV5: No. Auto de Requerimiento | AW5: Fecha Auto de Requerimiento | AX5: Nombre de quién proyectó | AY5: Radicado Oficio de entrada | AZ5: Fecha oficio de entrada | BA5: No. Acto Administrativo | BB5: Fecha Acto Administrativo | BC5: Nombre de quién proyectó | BD5: Otorgada | BE5: Negada | BF5: Fecha Notificación | BG5: Fecha ejecutoria | BH5: No. Radicado | BI5: Fecha Radicado | BJ5: No. Acto Administrativo | BK5: Fecha Acto Administrativo | BL5: Nombre de quién proyectó | BM5: Modifica/ Aclara / Confirma/ Adiciona /Niega | BN5: Fecha Notificación | BO5: No. Radicado | BP5: Fecha Radicado | BQ5: Auto Requer. | BR5: Fecha Requer. | BS5: Nombre de quién proyecto | BT5: No. Acto Administrativo | BU5: Fecha Act Administrativo | BV5: Nombre de quien proyectó | BW5: Cumple o NO | BX5: No. Radicado del usuario | BY5: Fecha Radicado | BZ5: Fecha de visita técnica | CA5: Fecha Informe técnico | CB5: Nombre del técnico | CC5: No. Acto Administrativo | CD5: Fecha Acto Administrativo | CE5: Nombre de quién proyectó | CF5: Cumple o NO | CH5: ULTIMA ACTULIZACION | CI5: FECHA ACTUALIZAICON
C6: C.A. 105/02 | E6: OCTAVIO MONTENEGRO LOPEZ | F6: 40128779 | G6: Predio Algarrobo | H6: Campohermoso | I6: 321 343 6905 – 313 840 2816 | J6: olviamontenegro@hotmail.com | K6: Teguas | L6: Nacimiento | M6: Superficial | N6: Sin Nombre | O6: Domestico Pecuario | P6: N/A | Q6: N/A | R6: N/A | S6: N/A | T6: N/A | U6: N/A | V6: N/A | W6: N/A | X6: N/A | Y6: N/A | Z6: N/A | AA6: N/A | AB6: N/A | AC6: N/A | AD6: N/A | AE6: N/A | AF6: N/A | AG6: N/A | AH6: N/A | AI6: N/A | AJ6: N/A | AK6: N/A | AL6: N/A | AM6: N/A | AN6: N/A | AO6: N/A | AP6: N/A | AQ6: N/A | AR6: N/A | AS6: N/A | AT6: N/A | AU6: N/A | AV6: N/A | AW6: N/A | AX6: N/A | AY6: N/A | AZ6: N/A | BA6: N/A | BB6: N/A | BC6: N/A | BD6: 952 544 1169 | BE6: N/A | BF6: 27/01/2003 23/07/2012 01/11/2022 | BG6: N/A | BH6: N/A | BI6: N/A | BJ6: N/A | BK6: N/A | BL6: N/A | BM6: N/A | BN6: N/A | BO6: N/A | BP6: N/A | BQ6: N/A | BR6: N/A | BS6: N/A | BT6: N/A | BU6: N/A | BV6: N/A | BW6: N/A | BX6: N/A | BY6: N/A | BZ6: N/A | CA6: N/A | CB6: N/A | CC6: N/A | CD6: N/A | CE6: N/A | CF6: N/A | CG6: N/A
C7: CA 145-02 | E7: MUNICIPIO DE JENESANO | F7: 891801376 | H7: Jenesano | J7: unidadserviciospublicos@jenesano-boyaca.gov.co | K7: Pulidos | L7: Superficial | M7: Quebrada | N7: La Unica | O7: Domestico | P7: N/A | Q7: N/A | R7: N/A | S7: N/A | T7: N/A | U7: N/A | V7: N/A | W7: N/A | X7: N/A | Y7: N/A | Z7: N/A | AA7: N/A | AB7: N/A | AC7: N/A | AD7: N/A | AE7: N/A | AF7: N/A | AG7: N/A | AH7: N/A | AI7: N/A | AJ7: N/A | AK7: N/A | AL7: N/A | AM7: N/A | AN7: N/A | AO7: N/A | AP7: N/A | AQ7: N/A | AR7: N/A | AS7: N/A | AT7: N/A | AU7: N/A | AV7: N/A | AW7: N/A | AX7: N/A | AY7: N/A | AZ7: N/A | BA7: 482 315 300 | BB7: 02/08/2002 03/07/2013 30/04/2025 | BC7: MILENA GALINDO | BD7: X | BF7: 45782 | BG7: 45796 | BH7: N/A | BI7: N/A | BJ7: N/A | BK7: N/A | BL7: N/A | BM7: N/A | BN7: N/A | BO7: 2025ER7341 | BP7: 45845 | BQ7: 2115 | BR7: 45992 | BS7: Karen B. | BT7: N/A | BU7: N/A | BV7: N/A | BW7: N/A | BX7: N/A | BY7: N/A | BZ7: N/A | CA7: N/A | CB7: N/A | CC7: N/A | CD7: N/A | CE7: N/A | CF7: N/A | CG7: PRORROGADA -Se requieren ajustes ajustes a las memorias(pazo 04-01-2026) | CH7: KAREN BARRETO | CI7: 46010
C8: CA 116-02 | E8: JOSÉ EVARISTO PORRAS, | F8: 4291640 | G8: Sector Agua Buena Vereda Bojirque Ventaquemada - Boyacá | H8: Ventaquemada | I8: 3219093882 | BA8: 416 469 286 | BB8: 12/07/2002 26/06/2012 25/04/2023 | BD8: x | BF8: 45153 | BG8: 45169 | BO8: 2026ER2745 | BP8: 46085 | BQ8: 575 | BR8: 202EE4169 | BS8: Milena G. | BT8: NA | BU8: NA | BV8: NA | BW8: NA | BX8: NA | BY8: NA | BZ8: NA | CA8: NA | CB8: NA | CC8: NA | CD8: NA | CE8: NA | CF8: NA | CG8: Pendiente Ajuste de Obras | CH8: Milena G | CI8: 31-4-26

Sheet CA 2004
A1: DATOS DE LA SOLICITUD | O1: APERTURÓ | P1: REQUERIMIENTO | W1: PAGO SERVICIOS DE EVALUACION | AB1: No. Oficio/ Auto de Requerimiento | AE1: CONTROL- DIAS TRANSCURRIDOS HASTA FECHA DE VISITA | AF1: CONCEPTO TECNICO | AV1: CONTROL- DIAS TRANSCURRIDOS DE LA RADICACION AL CONCEPTO CON Vo.Bo. | AW1: FECHA DE ASIGNACION CONCEPTO AL AREA JURIDICO | AX1: REQUERIMIENTO | BC1: ACTO ADMINISTRATIVO | BL1: RECURSO DE REPOSICION | BS1: MEMORIAS DE CALCULO | CB1: RECIBO A SATISFACCION DE OBRAS | CK1: ACTO ADMINISTRATIVO | EU1: SEGUIMIENTO | FD1: Observaciones de lo evidenciado en la visita técnica | FE1: Ultima Actualización
